Workbook

Sheet Resumen
A1: Fuente de alimentación multisalida para laboratorio — Documentación inicial
A2: Universidad Tecnológica de Pereira · Ingeniería Mecatrónica · Autor: Ronaldo
A4: Resultados clave
A5: Potencia máxima total de salida | B5: =Calculos!$C$20 -> 151.9 | C5: W
A6: Potencia al bus VIN DC (con pérdidas) | B6: =Calculos!$C$22 -> 176.74534 | C6: W
A7: Transformador seleccionado | B7: Antek AS-4220 — 400 VA, 2 × 20 V / 10 A en paralelo
A8: Uso del transformador (corriente RMS requerida / nominal) | B8: =Calculos!$C$79 -> 0.73981996
A9: Bus VIN DC — mínimo (peor caso) | B9: =Calculos!$C$52 -> 20.717891 | C9: V
A10: Bus VIN DC — mínimo requerido | B10: =Calculos!$C$59 -> 17.892967 | C10: V
A11: Bus VIN DC — máximo (peor caso) | B11: =Calculos!$C$63 -> 30.801643 | C11: V
A12: Capacitancia del filtro | B12: =Calculos!$C$49 -> 30000 | C12: µF
A13: Eficiencia total (red → salidas) | B13: =Calculos!$C$139 -> 0.74067202
A14: Potencia tomada de la red | B14: =Calculos!$C$138 -> 205.08403 | C14: W
A16: Índice de hojas
A17: =HYPERLINK("#Especificaciones!A1","Especificaciones") -> Especificaciones | B17: Datos cuantitativos y de topología (docente + decisiones)
A18: =HYPERLINK("#Req_Funcionales!A1","Req_Funcionales") -> Req_Funcionales | B18: Qué debe hacer el sistema
A19: =HYPERLINK("#Req_NoFuncionales!A1","Req_NoFuncionales") -> Req_NoFuncionales | B19: Cómo debe comportarse: seguridad, eficiencia, térmico, documentación
A20: =HYPERLINK("#Restricciones!A1","Restricciones") -> Restricciones | B20: Condiciones impuestas que limitan el diseño
A21: =HYPERLINK("#Lista_Componentes!A1","Lista_Componentes") -> Lista_Componentes | B21: Lista preliminar de componentes principales con fuente y estado
A22: =HYPERLINK("#Calculos!A1","Calculos") -> Calculos | B22: Cálculo del transformador, bus, rectificador, protecciones, ajuste y pistas
A23: =HYPERLINK("#Convertidores!A1","Convertidores") -> Convertidores | B23: Diseño de los cinco convertidores DC/DC por salida
A24: =HYPERLINK("#Decisiones!A1","Decisiones") -> Decisiones | B24: Datos pendientes del PDF Pag_9 con su decisión
A26: Leyenda de colores
A27: Texto azul con fondo amarillo | B27: Dato de entrada o supuesto: se puede editar y todo se recalcula.
A28: Texto negro | B28: Fórmula calculada.
A29: Texto verde | B29: Vínculo a otra hoja del libro.
A30: Fondo verde claro | B30: Resultado clave.
A32: Supuestos que conviene confirmar con el docente
A33: • Red de 120 V / 60 Hz con variación de ±10 %.
A34: • Las cinco salidas pueden estar a su corriente máxima al mismo tiempo (peor caso).
A35: • La etapa de red (IEC, fusible, interruptor, NTC, varistor) se cablea en el chasis; la PCB solo recibe el secundario.
A36: • GND común de las salidas, flotante respecto a tierra de protección.
A37: • La construcción física y las pruebas se confirman aparte (PDF §4.2).

Sheet Especificaciones
A1: Especificaciones del proyecto — datos cuantitativos y de topología
A2: Parte A y B: datos dados por el docente. Parte C: valores definidos o calculados en este diseño (vinculados a la hoja Calculos).
A3: N.º | B3: Tipo de salida | C3: Tensión (V) | D3: Corriente máx. (A) | E3: Potencia máx. (W) | F3: Convertidor DC/DC asignado | G3: Origen
A4: 1 | B4: Fija positiva | C4: 12 | D4: 5 | E4: =ABS(C4)*D4 -> 60 | F4: LM2678T-12 (reductor) | G4: Docente (PDF Tabla 1 y Tabla 3); convertidor: candidato validado
A5: 2 | B5: Fija positiva | C5: 5 | D5: 5 | E5: =ABS(C5)*D5 -> 25 | F5: LM2678T-5.0 (reductor) | G5: Docente (PDF Tabla 1 y Tabla 3); convertidor: candidato validado
A6: 3 | B6: Fija positiva | C6: 3.3 | D6: 3 | E6: =ABS(C6)*D6 -> 9.9 | F6: LM2678T-3.3 (reductor) | G6: Docente (PDF Tabla 1 y Tabla 3); convertidor: candidato validado
A7: 4 | B7: Fija negativa | C7: -12 | D7: 1 | E7: =ABS(C7)*D7 -> 12 | F7: TPS54560B (buck-boost inversor) | G7: Docente (PDF Tabla 1 y Tabla 3); convertidor: candidato validado
A8: 5 | B8: Variable 1,25–15 V (se toma 15 V para la potencia máxima) | C8: 15 | D8: 3 | E8: =ABS(C8)*D8 -> 45 | F8: LM2678T-ADJ (reductor ajustable) | G8: Docente (PDF Tabla 1 y Tabla 3); convertidor: candidato validado
B9: Potencia máxima total de salida (sin pérdidas) | E9: =SUM(E4:E8) -> 151.9 | G9: Debe coincidir con 151,9 W del PDF
A11: ID | B11: Parámetro | C11: Valor | D11: Unidad | E11: Estado | F11: Detalle | G11: Origen
A12: B. Topología y etapa de entrada (dados por el docente)
A13: ESP-01 | B13: Fuente de energía | C13: Red AC monofásica | E13: Dado | F13: A través de un transformador AC comercial. | G13: Docente (PDF Tabla 2)
A14: ESP-02 | B14: Rectificación | C14: Puente de diodos | E14: Dado | F14: GBJ3510 (35 A / 1000 V). | G14: Docente (PDF Tabla 2)
A15: ESP-03 | B15: Filtrado | C15: Capacitivo | E15: Dado | F15: 3 × 10 000 µF / 50 V en paralelo. | G15: Docente (PDF Tabla 2)
A16: ESP-04 | B16: Conversión | C16: DC/DC integrada en la PCB | E16: Dado | F16: Cinco convertidores independientes, uno por salida, desde el bus VIN DC. | G16: Docente (PDF Tabla 2, §6)
A17: ESP-05 | B17: Protecciones | C17: En tres niveles | E17: Dado | F17: Entrada (antes del transformador), bus DC (después del filtro) y una por cada salida. | G17: Docente (PDF §6)
A18: C. Valores definidos en este diseño (vinculados a la hoja Calculos)
A19: ESP-06 | B19: Tensión nominal de la red | C19: =Calculos!$C$5 -> 120 | D19: V rms | E19: Por confirmar | F19: Red de Colombia. Confirmar con el docente. | G19: Supuesto
A20: ESP-07 | B20: Frecuencia de la red | C20: =Calculos!$C$6 -> 60 | D20: Hz | E20: Por confirmar | G20: Supuesto
A21: ESP-08 | B21: Transformador | C21: Antek AS-4220 | E21: Definido | F21: Toroidal 400 VA, 2 × 20 V/10 A (en paralelo: 20 V / 20 A), primario dual 115/230 V, 50/60 Hz. | G21: Selección (hoja Calculos §5)
A22: ESP-09 | B22: Potencia de entrada al bus VIN DC (con pérdidas) | C22: =Calculos!$C$22 -> 176.74534 | D22: W | E22: Calculado | F22: Todas las salidas a su corriente máxima a la vez. | G22: Cálculo (hoja Convertidores)
A23: ESP-10 | B23: Potencia total tomada de la red | C23: =Calculos!$C$138 -> 205.08403 | D23: W | E23: Calculado | F23: Incluye pérdidas del puente y del transformador. | G23: Cálculo (hoja Calculos §10)
A24: ESP-11 | B24: Corriente DC máxima del bus | C24: =Calculos!$C$45 -> 8.2202218 | D24: A | E24: Calculado | F24: Peor caso: red −10 %, plena carga. | G24: Cálculo (hoja Calculos §4)
A25: ESP-12 | B25: Tensión MÍNIMA del bus VIN DC | C25: =Calculos!$C$52 -> 20.717891 | D25: V | E25: Calculado | F25: Debe ser ≥ mínimo requerido (ver ESP-13). | G25: Cálculo (hoja Calculos §4)
A26: ESP-13 | B26: Tensión mínima requerida del bus | C26: =Calculos!$C$59 -> 17.892967 | D26: V | E26: Calculado | F26: Para que el LM2678-12 regule y la salida variable llegue a 15 V. | G26: Cálculo (hoja Calculos §4)
A27: ESP-14 | B27: Tensión MÁXIMA del bus VIN DC | C27: =Calculos!$C$63 -> 30.801643 | D27: V | E27: Calculado | F27: Red +10 %, sin carga. Límite de los LM2678: 40 V. | G27: Cálculo (hoja Calculos §4)
A28: ESP-15 | B28: Rizado admisible del bus (pico a pico) | C28: =Calculos!$C$40 -> 3 | D28: V | E28: Definido | F28: Dato pendiente del PDF resuelto. | G28: Decisión de diseño
A29: ESP-16 | B29: Rizado real del bus (pico a pico) | C29: =Calculos!$C$51 -> 2.283395 | D29: V | E29: Calculado | F29: Con 30 000 µF a plena carga. | G29: Cálculo (hoja Calculos §4)
A30: ESP-17 | B30: Capacitancia total del bus | C30: =Calculos!$C$49 -> 30000 | D30: µF | E30: Definido | F30: 3 × 10 000 µF / 50 V. | G30: Cálculo (hoja Calculos §4)
A31: ESP-18 | B31: Tolerancia de regulación de cada salida | C31: =Calculos!$C$12 -> 0.03 | D31: ±% | E31: Definido | F31: ±2 % a 25 °C, ±3 % en temperatura. | G31: Hoja de datos LM2678
A32: ESP-19 | B32: Rizado máximo de cada salida | C32: =Calculos!$C$13 -> 0.01 | D32: % de Vout | E32: Definido | F32: Pico a pico. | G32: Hoja de datos LM2678 §7.1.3
A33: ESP-20 | B33: Eficiencia total (red → salidas) | C33: =Calculos!$C$139 -> 0.74067202 | E33: Calculado | F33: Objetivo ≥ 70 %. | G33: Cálculo (hoja Calculos §10)
A34: ESP-21 | B34: Referencia común (tierra) | C34: GND común | E34: Definido | F34: Las cinco salidas comparten GND; aislado de la red por el transformador; chasis a PE. | G34: Decisión de diseño
A35: ESP-22 | B35: Condiciones ambientales de diseño | C35: =Calculos!$C$10 -> 40 | D35: °C | E35: Definido | F35: Temperatura interna del gabinete; Tj ≤ 125 °C. | G35: Supuesto de diseño

Sheet Req_Funcionales
A1: Requerimientos funcionales — qué debe hacer el sistema
A2: Cada fila es un requisito independiente (viñeta). «Valor de diseño» se vincula con la hoja Calculos / Convertidores; «Estado» se evalúa automáticamente.
A3: ID | B3: Requisito | C3: Umbral | D3: Unidad | E3: Valor de diseño | F3: Estado | G3: Método de verificación | H3: Origen / referencia
A4: A. Etapa de entrada y bus VIN DC
A5: RF-01 | B5: La fuente debe tomar la energía de la red AC monofásica a través de un transformador comercial. | C5: — | E5: — | F5: Por inspección | G5: Inspección | H5: Docente (PDF §2.1, §4.2)
A6: RF-02 | B6: El transformador AC debe reducir la tensión de la red y aislar galvánicamente las salidas. | C6: — | E6: — | F6: Por inspección | G6: Inspección | H6: Docente (PDF §2.1)
A7: RF-03 | B7: La tensión alterna del secundario debe rectificarse con un puente de diodos de onda completa. | C7: — | E7: — | F7: Por inspección | G7: Inspección | H7: Docente (PDF §2.1, §5.1)
A8: RF-04 | B8: El filtrado capacitivo debe mantener el rizado del bus VIN DC por debajo del límite en el peor caso (plena carga, red −10 %). | C8: =Calculos!$C$40 -> 3 | D8: V pp | E8: =Calculos!$C$51 -> 2.283395 | F8: =IF(E8<=C8,"Cumple","NO CUMPLE") -> Cumple | G8: Cálculo (hoja Calculos §4) | H8: Docente (PDF §2.1) + decisión de diseño
A9: RF-05 | B9: El bus VIN DC debe mantenerse por encima de la tensión mínima requerida en el peor caso, para que la salida variable llegue a 15 V y el convertidor de +12 V regule. | C9: =Calculos!$C$59 -> 17.892967 | D9: V | E9: =Calculos!$C$52 -> 20.717891 | F9: =IF(E9>=C9,"Cumple","NO CUMPLE") -> Cumple | G9: Cálculo (hoja Calculos §4) | H9: Docente (PDF §4.2: bus con margen > 15 V)
A10: RF-06 | B10: El bus VIN DC no debe superar la tensión máxima de entrada de los convertidores con red +10 % y sin carga. | C10: =Calculos!$C$64 -> 40 | D10: V | E10: =Calculos!$C$63 -> 30.801643 | F10: =IF(E10<=C10,"Cumple","NO CUMPLE") -> Cumple | G10: Cálculo (hoja Calculos §4) | H10: Hoja de datos LM2678
A11: RF-07 | B11: El transformador debe poder entregar la corriente RMS que exige el rectificador con filtro capacitivo a plena carga. | C11: =Calculos!$C$73 -> 14.796399 | D11: A rms | E11: =Calculos!$C$30 -> 20 | F11: =IF(E11>=C11,"Cumple","NO CUMPLE") -> Cumple | G11: Cálculo (hoja Calculos §5) | H11: Decisión de diseño
A12: B. Salidas reguladas (cada una con su convertidor DC/DC)
A13: RF-08 | B13: Entregar una salida fija de +12 V con corriente máxima de 5 A. | C13: 5 | D13: A | E13: =Convertidores!$C$44 -> 5.1022119 | F13: =IF(E13>=C13,"Cumple","NO CUMPLE") -> Cumple | G13: Prueba con carga electrónica | H13: Docente (PDF Tabla 1)
A14: RF-09 | B14: Entregar una salida fija de +5 V con corriente máxima de 5 A. | C14: 5 | D14: A | E14: =Convertidores!$D$44 -> 5.3553575 | F14: =IF(E14>=C14,"Cumple","NO CUMPLE") -> Cumple | G14: Prueba con carga electrónica | H14: Docente (PDF Tabla 1)
A15: RF-10 | B15: Entregar una salida fija de +3,3 V con corriente máxima de 3 A. | C15: 3 | D15: A | E15: =Convertidores!$E$44 -> 5.4586263 | F15: =IF(E15>=C15,"Cumple","NO CUMPLE") -> Cumple | G15: Prueba con carga electrónica | H15: Docente (PDF Tabla 1)
A16: RF-11 | B16: Entregar una salida fija negativa de −12 V con corriente máxima de 1 A (convertidor inversor). | C16: 1 | D16: A | E16: =Convertidores!$F$44 -> 2.9838782 | F16: =IF(E16>=C16,"Cumple","NO CUMPLE") -> Cumple | G16: Prueba con carga electrónica | H16: Docente (PDF Tabla 1)
A17: RF-12 | B17: Entregar una salida variable con corriente máxima de 3 A. | C17: 3 | D17: A | E17: =Convertidores!$G$44 -> 5.433495 | F17: =IF(E17>=C17,"Cumple","NO CUMPLE") -> Cumple | G17: Prueba con carga electrónica | H17: Docente (PDF Tabla 1)
A18: RF-13 | B18: La salida variable debe poder ajustarse hasta su valor mínimo de 1,25 V. | C18: 1.25 | D18: V | E18: =Calculos!$C$132 -> 1.2491511 | F18: =IF(E18<=C18,"Cumple","NO CUMPLE") -> Cumple | G18: Medición con multímetro | H18: Docente (PDF Tabla 1)
A19: RF-14 | B19: La salida variable debe poder ajustarse hasta cerca de 15 V (dentro de 2 %). | C19: 14.7 | D19: V | E19: =Calculos!$C$133 -> 14.890639 | F19: =IF(E19>=C19,"Cumple","NO CUMPLE") -> Cumple | G19: Medición con multímetro | H19: Docente (PDF Tabla 1)
A20: RF-15 | B20: El ajuste de la salida variable debe hacerse con un potenciómetro multivuelta accesible. | C20: — | E20: — | F20: Por inspección | G20: Inspección | H20: Decisión de diseño
A21: RF-16 | B21: Las cinco salidas deben ser alimentadas por cinco convertidores DC/DC independientes conectados en paralelo al bus VIN DC. | C21: — | E21: — | F21: Por inspección | G21: Inspección | H21: Docente (PDF §6)
A22: RF-17 | B22: Las cinco salidas deben compartir una referencia común (GND). | C22: — | E22: — | F22: Por inspección | G22: Inspección | H22: Decisión de diseño (PDF §9)
A23: RF-18 | B23: Todas las salidas deben poder entregar su corriente máxima al mismo tiempo (diseño de peor caso). | C23: =Calculos!$C$19 -> 151.9 | D23: W | E23: =Calculos!$C$20 -> 151.9 | F23: =IF(E23>=C23,"Cumple","NO CUMPLE") -> Cumple | G23: Prueba a plena carga | H23: Decisión de diseño (PDF §9)
A24: RF-19 | B24: Cada convertidor debe limitar su corriente y apagarse por sobretemperatura (protección integrada en el IC). | C24: — | E24: — | F24: Por inspección | G24: Inspección (hoja de datos) y prueba de cortocircuito | H24: Hoja de datos LM2678 / TPS54560B
A25: C. Protecciones, maniobra y conexión
A26: RF-20 | B26: Debe existir un interruptor general de encendido en la entrada de red. | C26: — | E26: — | F26: Por inspección | G26: Inspección | H26: Decisión de diseño
A27: RF-21 | B27: Protección de entrada (antes del transformador): fusible de acción lenta, varistor contra sobretensiones y NTC limitador de arranque. | C27: =Calculos!$C$92 -> 3.4265346 | D27: A | E27: =Calculos!$C$93 -> 4 | F27: =IF(E27>=C27,"Cumple","NO CUMPLE") -> Cumple | G27: Cálculo (hoja Calculos §6) | H27: Docente (PDF §6)
A28: RF-22 | B28: Protección del bus DC (después del filtrado): fusible, TVS y resistor de sangrado. | C28: =Calculos!$C$117 -> 10.960296 | D28: A | E28: =Calculos!$C$118 -> 15 | F28: =IF(E28>=C28,"Cumple","NO CUMPLE") -> Cumple | G28: Cálculo (hoja Calculos §8) | H28: Docente (PDF §6)
A29: RF-23 | B29: Protección independiente en cada salida regulada: PTC reiniciable y diodo de sujeción (TVS o Zener). | C29: — | E29: — | F29: Por inspección | G29: Inspección y prueba de sobrecarga | H29: Docente (PDF §6)
A30: RF-24 | B30: Cada salida debe terminar en bornes (binding posts) de 15 A, un positivo por salida más bornes de GND común. | C30: 5 | D30: A | E30: 15 | F30: =IF(E30>=C30,"Cumple","NO CUMPLE") -> Cumple | G30: Inspección | H30: Docente (PDF §8.1)

Sheet Req_NoFuncionales
A1: Requerimientos no funcionales — cómo debe comportarse el sistema
A2: Seguridad, confiabilidad, eficiencia, regulación, térmico y documentación. Cada fila es un requisito independiente.
A3: ID | B3: Requisito | C3: Umbral | D3: Unidad | E3: Valor de diseño | F3: Estado | G3: Método de verificación | H3: Origen / referencia
A4: A. Seguridad
A5: RNF-01 | B5: Aislamiento galvánico entre la red y todas las salidas (primario–secundario). | C5: 1500 | D5: V | E5: =Calculos!$C$36 -> 3500 | F5: =IF(E5>=C5,"Cumple","NO CUMPLE") -> Cumple | G5: Hoja de datos (prueba del fabricante) | H5: IEC 61010-1 (referencia, confirmar) / Antek AS-4220
A6: RNF-02 | B6: Todas las tensiones accesibles deben ser extra-bajas (< 60 V DC). | C6: 60 | D6: V | E6: =Calculos!$C$63 -> 30.801643 | F6: =IF(E6<=C6,"Cumple","NO CUMPLE") -> Cumple | G6: Cálculo (hoja Calculos §4) | H6: Buena práctica de seguridad
A7: RNF-03 | B7: El chasis metálico debe conectarse a tierra de protección (PE) mediante la entrada IEC; el GND de las salidas queda flotante, con puente opcional al chasis. | C7: — | E7: — | F7: Por inspección | G7: Inspección | H7: Decisión de diseño
A8: RNF-04 | B8: Las protecciones deben dimensionarse sin usar el fusible por encima del 75 % de su corriente nominal. | C8: 0.75 | E8: =Calculos!$C$17 -> 0.75 | F8: =IF(E8<=C8,"Cumple","NO CUMPLE") -> Cumple | G8: Inspección de cálculos | H8: Buena práctica de diseño
A9: RNF-05 | B9: Los capacitores del bus deben tener tensión nominal ≥ 1,25 × la tensión máxima del bus. | C9: 1.25 | D9: × | E9: =Calculos!$C$68 -> 1.62329 | F9: =IF(E9>=C9,"Cumple","NO CUMPLE") -> Cumple | G9: Cálculo (hoja Calculos §4) | H9: Buena práctica de diseño
A10: B. Desempeño eléctrico
A11: RNF-06 | B11: Regulación de cada salida dentro de ±3 % en todo el rango de carga y temperatura. | C11: 0.03 | D11: ±% | E11: =Calculos!$C$12 -> 0.03 | F11: =IF(E11<=C11,"Cumple","NO CUMPLE") -> Cumple | G11: Prueba con carga electrónica | H11: Hoja de datos LM2678 (decisión de diseño)
A12: RNF-07 | B12: Rizado pico a pico de cada salida ≤ 1 % de su tensión nominal. | C12: =Calculos!$C$13 -> 0.01 | D12: % de Vout | E12: =MAX(Convertidores!C52:G52) -> 0.0094714211 | F12: =IF(E12<=C12,"Cumple","NO CUMPLE") -> Cumple | G12: Cálculo y medición con osciloscopio (20 MHz) | H12: Decisión de diseño (PDF §9)
A13: RNF-08 | B13: Eficiencia total (red → salidas) a plena carga. | C13: =Calculos!$C$140 -> 0.7 | E13: =Calculos!$C$139 -> 0.74067202 | F13: =IF(E13>=C13,"Cumple","NO CUMPLE") -> Cumple | G13: Cálculo (hoja Calculos §10) y prueba | H13: Decisión de diseño (PDF §9)
A14: RNF-09 | B14: Eficiencia combinada de la etapa DC/DC ≥ 80 %. | C14: 0.8 | E14: =Calculos!$C$23 -> 0.85942861 | F14: =IF(E14>=C14,"Cumple","NO CUMPLE") -> Cumple | G14: Cálculo | H14: Decisión de diseño
A15: RNF-10 | B15: El transformador no debe operar por encima del 83 % de su capacidad de corriente (margen del 20 %). | C15: =1/(1+Calculos!$C$75) -> 0.83333333 | E15: =Calculos!$C$79 -> 0.73981996 | F15: =IF(E15<=C15,"Cumple","NO CUMPLE") -> Cumple | G15: Cálculo (hoja Calculos §5) | H15: Decisión de diseño
A16: RNF-11 | B16: Recuperación suave tras un cortocircuito en cada salida (sin histéresis del límite de corriente). | C16: — | E16: — | F16: Por prueba | G16: Prueba de cortocircuito (hoja de datos LM2678 §7.1.7) | H16: Hoja de datos LM2678
A17: C. Térmico y confiabilidad
A18: RNF-12 | B18: Temperatura de unión de los convertidores ≤ 125 °C con 40 °C de ambiente interno. | C18: =Calculos!$C$11 -> 125 | D18: °C | E18: =MAX(Convertidores!C76:G76) -> 112 | F18: =IF(E18<=C18,"Cumple","NO CUMPLE") -> Cumple | G18: Cálculo (hoja Convertidores §9) y prueba térmica | H18: Hoja de datos
A19: RNF-13 | B19: El puente rectificador debe llevar disipador con resistencia térmica suficiente. | C19: =Calculos!$C$113 -> 3.6001607 | D19: °C/W | E19: =Calculos!$C$114 -> 3 | F19: =IF(E19<=C19,"Cumple","NO CUMPLE") -> Cumple | G19: Cálculo (hoja Calculos §7) | H19: Hoja de datos GBJ3510
A20: RNF-14 | B20: Vida útil de los electrolíticos del bus ≥ 5000 h a 105 °C. | C20: 5000 | D20: h | E20: 5000 | F20: =IF(E20>=C20,"Cumple","NO CUMPLE") -> Cumple | G20: Hoja de datos | H20: Nichicon LKS1H103MESB
A21: RNF-15 | B21: Pistas de potencia dimensionadas por IPC-2221 con elevación de temperatura ≤ 20 °C. | C21: 20 | D21: °C | E21: =Calculos!$C$146 -> 20 | F21: =IF(E21<=C21,"Cumple","NO CUMPLE") -> Cumple | G21: Cálculo (hoja Calculos §11) | H21: IPC-2221
A22: RNF-16 | B22: Disipación de calor total compatible con el gabinete (se requiere ventilación natural o forzada). | C22: — | D22: W | E22: =Calculos!$C$142 -> 53.184027 | F22: Por inspección | G22: Inspección / prueba térmica | H22: Cálculo (hoja Calculos §10)
A23: D. Documentación, trazabilidad y diseño de la PCB
A24: RNF-17 | B24: Cada componente debe registrarse con su fuente, enlace y características principales. | C24: — | E24: — | F24: Por inspección | G24: Inspección (hoja Lista_Componentes) | H24: Docente (PDF §8.2)
A25: RNF-18 | B25: Cada componente debe tener símbolo, huella y modelo 3D descargables de fuentes reconocidas (TI, DigiKey, Ultra Librarian, SnapEDA). | C25: — | E25: — | F25: Por inspección | G25: Inspección | H25: Docente (PDF §3.2, §8.3)
A26: RNF-19 | B26: Los componentes deben conseguirse en el mercado local o por importación (DigiKey/Mouser). | C26: — | E26: — | F26: Por inspección | G26: Inspección | H26: Docente (PDF §4.2)
A27: RNF-20 | B27: El layout debe seguir la guía de TI (AN-1229): lazos de corriente AC cortos, planos de tierra amplios y cobre de 2 oz. | C27: — | E27: — | F27: Por inspección | G27: Inspección | H27: Hoja de datos LM2678 §7.4
A28: RNF-21 | B28: Debe haber puntos de prueba y serigrafía legible en cada salida; fusibles accesibles para reemplazo. | C28: — | E28: — | F28: Por inspección | G28: Inspección | H28: Decisión de diseño

Sheet Restricciones
A1: Restricciones de diseño — condiciones impuestas que limitan las decisiones
A2: Las restricciones B se derivan de las hojas de datos de los componentes seleccionados; se verifican contra los cálculos.
A3: ID | B3: Requisito | C3: Umbral | D3: Unidad | E3: Valor de diseño | F3: Estado | G3: Método de verificación | H3: Origen / referencia
A4: A. Restricciones impuestas por el docente (PDF §4.2)
A5: RD-01 | B5: La energía de entrada viene de la red AC mediante un transformador comercial; su capacidad limita la potencia total disponible. | C5: =Calculos!$C$26 -> 400 | D5: VA | E5: =Calculos!$C$74 -> 295.92799 | F5: =IF(E5>=C5,"Cumple","NO CUMPLE") -> NO CUMPLE | G5: Cálculo (hoja Calculos §5) | H5: Docente (PDF §4.2)
A6: RD-02 | B6: Topología impuesta: puente de diodos, filtrado capacitivo y conversión DC/DC integrada en la PCB. | C6: — | E6: — | F6: Por inspección | G6: Inspección | H6: Docente (PDF §4.2)
A7: RD-03 | B7: Las salidas son las cinco de la Tabla 1 y ninguna puede superar su corriente máxima. | C7: — | E7: — | F7: Por inspección | G7: Inspección | H7: Docente (PDF §4.2)
A8: RD-04 | B8: La salida variable está limitada a 1,25–15 V, lo que exige un bus VIN DC con margen por encima de 15 V. | C8: =Calculos!$C$59 -> 17.892967 | D8: V | E8: =Calculos!$C$52 -> 20.717891 | F8: =IF(E8>=C8,"Cumple","NO CUMPLE") -> Cumple | G8: Cálculo (hoja Calculos §4) | H8: Docente (PDF §4.2)
A9: RD-05 | B9: Los elementos deben ser comerciales, con documentación del fabricante y con modelos descargables para la PCB. | C9: — | E9: — | F9: Por inspección | G9: Inspección | H9: Docente (PDF §4.2)
A10: RD-06 | B10: Los elementos deben poder conseguirse en el medio local o por importación (restricción válida del proyecto). | C10: — | E10: — | F10: Por inspección | G10: Inspección | H10: Docente (PDF §4.2)
A11: RD-07 | B11: No se diseña el transformador: se selecciona un transformador comercial. | C11: — | E11: — | F11: Por inspección | G11: Inspección | H11: Docente (PDF §4.2)
A12: RD-08 | B12: La construcción física y las pruebas de la fuente se confirmarán con el docente. | C12: — | E12: — | F12: Por inspección | G12: Inspección | H12: Docente (PDF §4.2)
A13: B. Restricciones derivadas de los componentes elegidos
A14: RD-09 | B14: LM2678-12 exige tensión de entrada ≥ 15 V. | C14: 15 | D14: V | E14: =Calculos!$C$52 -> 20.717891 | F14: =IF(E14>=C14,"Cumple","NO CUMPLE") -> Cumple | G14: Cálculo | H14: Hoja de datos LM2678 §5.7
A15: RD-10 | B15: Los LM2678 admiten como máximo 40 V de entrada en operación (45 V absolutos). | C15: 40 | D15: V | E15: =Calculos!$C$63 -> 30.801643 | F15: =IF(E15<=C15,"Cumple","NO CUMPLE") -> Cumple | G15: Cálculo | H15: Hoja de datos LM2678 §5.3
A16: RD-11 | B16: TPS54560B: la tensión vista por el IC (Vin + |Vout|) no debe superar 60 V. | C16: 60 | D16: V | E16: =Convertidores!$F$19 -> 42.801643 | F16: =IF(E16<=C16,"Cumple","NO CUMPLE") -> Cumple | G16: Cálculo (hoja Convertidores §2) | H16: Hoja de datos TPS54560B
A17: RD-12 | B17: Ciclo de trabajo máximo del LM2678: 91 %. | C17: 0.91 | E17: =MAX(Convertidores!C27:E27,Convertidores!G27) -> 0.74312404 | F17: =IF(E17<=C17,"Cumple","NO CUMPLE") -> Cumple | G17: Cálculo (hoja Convertidores §3) | H17: Hoja de datos LM2678 §5.9
A18: RD-13 | B18: Con Vout > 6 V y D > 50 % el fabricante recomienda cargas ≤ I_lim/2 para evitar histéresis del límite de corriente (aplica a +12 V y a la variable en 15 V). Riesgo conocido: validar con prueba de cortocircuito y, si aparece, reducir Cout de la variable. | C18: =Convertidores!G43/2 -> 2.875 | D18: A | E18: =Convertidores!$G$9 -> 3 | F18: =IF(E18<=C18,"Cumple","REVISAR EN PRUEBA") -> REVISAR EN PRUEBA | G18: Prueba de cortocircuito | H18: Hoja de datos LM2678 §7.1.7
A19: RD-14 | B19: Disipadores de los LM2678 (TO-220): resistencia térmica ≤ la mínima requerida entre las cuatro salidas. | C19: =MIN(Convertidores!C73:E73,Convertidores!G73) -> 18.25 | D19: °C/W | E19: =Convertidores!$C$74 -> 12 | F19: =IF(E19<=C19,"Cumple","NO CUMPLE") -> Cumple | G19: Cálculo (hoja Convertidores §9) | H19: Hoja de datos LM2678 §5.4
A20: RD-15 | B20: La corriente de rizado RMS por capacitor del bus no debe exceder la nominal del capacitor elegido (validar en la hoja de datos). | C20: — | D20: A rms | E20: =Calculos!$C$84 -> 4.1009672 | F20: Por inspección | G20: Inspección (hoja de datos del capacitor) | H20: Cálculo (hoja Calculos §5)
A21: RD-16 | B21: Los cuatro LM2678 comparten el bus: se usa cobre de 2 oz y un plano de tierra continuo (recomendación del fabricante). | C21: — | E21: — | F21: Por inspección | G21: Inspección | H21: Hoja de datos LM2678 §7.4
A22: RD-17 | B22: La etapa de red (módulo IEC, fusible, interruptor, NTC y varistor) se cablea en el chasis; la PCB recibe solo el secundario de baja tensión. | C22: — | E22: — | F22: Por inspección | G22: Inspección | H22: Decisión de diseño (confirmar con el docente)

Sheet Lista_Componentes
A1: Lista preliminar de componentes principales
A2: Cada componente trae su función, su justificación (cálculo en las hojas Calculos / Convertidores), su fuente y el estado de verificación. Los enlaces de búsqueda de DigiKey y SnapEDA se abren con el número de parte.
A3: ID | B3: Bloque | C3: Componente | D3: Referencia (MPN) | E3: Fabricante | F3: Características clave | G3: Cant. | H3: Función | I3: Justificación / cálculo | J3: Montaje | K3: Fuente (hoja de datos / distribuidor) | L3: Modelos CAD (símbolo, huella, 3D) | M3: Estado de verificación
A4: ENTRADA DE RED (cableada en el chasis)
A5: C-01 | B5: Entrada de red | C5: Módulo IEC C14 con interruptor y portafusible | D5: Schurter DD12 (familia) | E5: Schurter | F5: IEC 60320 C14, 10 A / 250 V, interruptor, portafusible 5 × 20 mm, terminal PE | G5: 1 | H5: Conexión de red, interruptor general y soporte del fusible de entrada | I5: RF-20, RF-21; I primario máx. en Calculos §5 | J5: Chasis | K5: https://www.digikey.com/en/products/result?keywords=Schurter%20DD12 | L5: https://www.snapeda.com/search?q=Schurter%20DD12 | M5: Familia recomendada — confirmar MPN exacto
A6: C-02 | B6: Protección de entrada | C6: Fusible 5 × 20 mm, acción lenta | D6: Littelfuse 0215004.MXP | E6: Littelfuse | F6: T4A, 250 V (≥ I_prim/0,75 — ver Calculos §6) | G6: 2 | H6: Protege el primario del transformador (1 en uso + 1 repuesto) | I6: Calculos §6: fusible ≥ I_primario_max / 0,75 | J6: Chasis | K6: https://www.digikey.com/en/products/result?keywords=0215004.MXP | L6: https://www.snapeda.com/search?q=0215004.MXP | M6: Referencia estándar — validar MPN y stock
A7: C-03 | B7: Protección de entrada | C7: Varistor (MOV) 14 mm | D7: TDK EPCOS S14K150 (B72214S0151K101) | E7: TDK / EPCOS | F7: 150 V AC continuos, disco 14 mm | G7: 1 | H7: Limita sobretensiones de la red | I7: Calculos §6: V_MOV ≥ 1,1 · V_red máx. | J7: Chasis | K7: https://www.digikey.com/en/products/result?keywords=S14K150 | L7: https://www.snapeda.com/search?q=S14K150 | M7: Referencia estándar — validar MPN y stock
A8: C-04 | B8: Protección de entrada | C8: Termistor NTC limitador de arranque | D8: Ametherm SL32 10015 | E8: Ametherm | F8: 10 Ω a 25 °C, 15 A en régimen | G8: 1 | H8: Limita el pico de arranque del toroidal y de los 30 000 µF | I8: Calculos §6: pico ≈ 19 A < 20 A | J8: Chasis | K8: https://www.digikey.com/en/products/result?keywords=SL32%2010015 | L8: https://www.snapeda.com/search?q=SL32%2010015 | M8: Referencia estándar — validar MPN y stock
A9: TRANSFORMADOR AC
A10: C-05 | B10: Transformador | C10: Transformador toroidal de potencia | D10: Antek AS-4220 | E10: Antek Inc. | F10: 400 VA; primario dual 115/230 V, 50/60 Hz; 2 × 20 V / 10 A (en paralelo 20 V / 20 A); pantalla electrostática; aislamiento > 3500 V | G10: 1 | H10: Reduce y aísla la tensión de red | I10: Calculos §5: uso ≈ 74 % con 20 % de margen; AS-3220 (300 VA) queda al límite | J10: Chasis | K10: https://www.antekinc.com/as-4220-400va-20v-transformer/ | L10: Proporcionar medidas del fabricante (5,1" Ø × 3,1") | M10: Verificado en hoja de datos del fabricante
A11: RECTIFICACIÓN Y FILTRADO
A12: C-06 | B12: Rectificación | C12: Borne de tornillo para PCB (secundario AC) | D12: Phoenix Contact MKDSP 10 (paso 10,16 mm) | E12: Phoenix Contact | F12: ≥ 20 A, 2 posiciones | G12: 1 | H12: Entrada del secundario del transformador a la PCB | I12: Calculos §5: I_sec rms ≈ 15 A | J12: PCB | K12: https://www.digikey.com/en/products/result?keywords=MKDSP%2010 | L12: https://www.snapeda.com/search?q=MKDSP%2010 | M12: Familia recomendada — confirmar MPN exacto
A13: C-07 | B13: Rectificación | C13: Puente rectificador monofásico | D13: GBJ3510 | E13: Diodes Inc. | F13: 35 A (con disipador), 1000 V, VF 1,1 V @ 17,5 A, IFSM 400 A | G13: 1 | H13: Rectifica el AC del secundario | I13: Calculos §7: I ≥ 2·I_DC, V_RRM ≥ 2·V_pico | J13: PCB | K13: https://www.diodes.com/assets/Datasheets/GBJ3510.pdf | L13: https://www.snapeda.com/search?q=GBJ3510 | M13: Verificado en hoja de datos del fabricante
A14: C-08 | B14: Rectificación | C14: Disipador del puente | D14: Perfil de aluminio / fijación al chasis | E14: Genérico | F14: Rθsa ≤ 3,0 °C/W, con grasa térmica | G14: 1 | H14: Evacua ≈ 18 W del puente | I14: Calculos §7: Rθsa requerido ≈ 3,6 °C/W | J14: Chasis / PCB | K14: https://www.digikey.com/en/products/result?keywords=heat%20sink%20bridge%20rectifier%20GBJ | L14: No aplica | M14: Valor definido — validar referencia vigente
A15: C-09 | B15: Filtrado | C15: Capacitor electrolítico snap-in 10 000 µF / 50 V | D15: Nichicon LKS1H103MESB | E15: Nichicon | F15: 10 000 µF, 50 V, 105 °C, 5000 h; verificar corriente de rizado ≥ valor de Calculos §5 | G15: 3 | H15: Forma el bus VIN DC y reduce el rizado | I15: Calculos §4: C ≥ 22 900 µF; 3 × 10 000 µF = 30 000 µF | J15: PCB | K15: https://www.newark.com/c/passive-components/capacitors/aluminium-electrolytic-capacitors?brand=nichicon&capacitance=10000uf | L15: https://www.snapeda.com/search?q=LKS1H103MESB | M15: Verificado en catálogo (fabricante/distribuidor)
A16: C-10 | B16: Filtrado | C16: Resistor de sangrado 4,7 kΩ / 2 W | D16: Genérico (película metálica) | E16: Yageo / Vishay | F16: 4,7 kΩ, 2 W, 1 % | G16: 1 | H16: Descarga los capacitores al apagar (τ ≈ 141 s) | I16: Calculos §8 | J16: PCB | K16: https://www.digikey.com/en/products/result?keywords=4.7k%202W%20resistor | L16: No aplica | M16: Referencia estándar — validar MPN y stock
A17: PROTECCIÓN DEL BUS DC
A18: C-11 | B18: Protección del bus | C18: Fusible ATO 15 A y portafusible para PCB | D18: Littelfuse 0287015.PXCN | E18: Littelfuse | F18: 15 A, 32 V, tipo ATO | G18: 2 | H18: Protege el bus VIN DC (1 en uso + 1 repuesto) | I18: Calculos §8: fusible ≥ I_DC/0,75 | J18: PCB | K18: https://www.digikey.com/en/products/result?keywords=0287015.PXCN | L18: https://www.snapeda.com/search?q=0287015.PXCN | M18: Referencia estándar — validar MPN y stock
A19: C-12 | B19: Protección del bus | C19: TVS unidireccional 1500 W | D19: Littelfuse SMCJ30A | E19: Littelfuse | F19: Vwm 30 V, Vbr 33,3–36,8 V, Vc 48,4 V | G19: 1 | H19: Recorta transitorios en el bus | I19: Calculos §8: Vbr > V_bus máx. | J19: PCB | K19: https://www.digikey.com/en/products/result?keywords=SMCJ30A | L19: https://www.snapeda.com/search?q=SMCJ30A | M19: Referencia estándar — validar MPN y stock
A20: CONVERTIDORES DC/DC
A21: C-13 | B21: +12 V / 5 A | C21: Regulador reductor 5 A, 12 V fijo | D21: LM2678T-12/NOPB | E21: Texas Instruments | F21: Vin 15–40 V, 5 A, 260 kHz, TO-220-7 | G21: 1 | H21: Genera +12 V | I21: Hoja Convertidores (columna +12 V) | J21: PCB + disipador | K21: https://www.ti.com/lit/ds/symlink/lm2678.pdf | L21: https://www.ti.com/product/LM2678 | M21: Verificado en hoja de datos del fabricante
A22: C-14 | B22: +5 V / 5 A | C22: Regulador reductor 5 A, 5 V fijo | D22: LM2678T-5.0/NOPB | E22: Texas Instruments | F22: Vin 8–40 V, 5 A, TO-220-7 | G22: 1 | H22: Genera +5 V | I22: Hoja Convertidores (columna +5 V) | J22: PCB + disipador | K22: https://www.ti.com/lit/ds/symlink/lm2678.pdf | L22: https://www.ti.com/product/LM2678 | M22: Verificado en hoja de datos del fabricante
A23: C-15 | B23: +3,3 V / 3 A | C23: Regulador reductor 5 A, 3,3 V fijo | D23: LM2678T-3.3/NOPB | E23: Texas Instruments | F23: Vin 8–40 V, 5 A, TO-220-7 | G23: 1 | H23: Genera +3,3 V | I23: Hoja Convertidores (columna +3,3 V) | J23: PCB + disipador | K23: https://www.ti.com/lit/ds/symlink/lm2678.pdf | L23: https://www.ti.com/product/LM2678 | M23: Verificado en hoja de datos del fabricante
A24: C-16 | B24: Variable / 3 A | C24: Regulador reductor 5 A, ajustable | D24: LM2678T-ADJ/NOPB | E24: Texas Instruments | F24: Vout 1,2–37 V, 5 A, TO-220-7 | G24: 1 | H24: Genera la salida variable 1,25–15 V | I24: Hoja Convertidores (columna Variable) y Calculos §9 | J24: PCB + disipador | K24: https://www.ti.com/lit/ds/symlink/lm2678.pdf | L24: https://www.ti.com/product/LM2678 | M24: Verificado en hoja de datos del fabricante
A25: C-17 | B25: −12 V / 1 A | C25: Convertidor reductor 60 V / 5 A (en configuración inversora) | D25: TPS54560BDDAR | E25: Texas Instruments | F25: Vin 4,5–60 V, 5 A, HSOIC-8 PowerPAD; configuración inversora según §8.3 del datasheet y nota SLVA317 | G25: 1 | H25: Genera −12 V a partir del bus | I25: Hoja Convertidores (columna −12 V) | J25: PCB | K25: https://www.ti.com/lit/ds/symlink/tps54560b.pdf | L25: https://www.ti.com/product/TPS54560B | M25: Verificado en hoja de datos del fabricante
A26: C-18 | B26: +12 V, +5 V, +3,3 V | C26: Inductor 22 µH, 5,22 A | D26: Renco RL-1283-22-43 (L41) | E26: Renco / Pulse | F26: 22 µH, 5,22 A, núcleo de ferrita, through-hole | G26: 3 | H26: Filtro de salida de los tres convertidores fijos | I26: Hoja Convertidores §4: L ≥ L_mín | J26: PCB | K26: https://www.ti.com/lit/ds/symlink/lm2678.pdf | L26: https://www.snapeda.com/search?q=RL-1283-22-43 | M26: Verificado en hoja de datos del fabricante (Tabla 7-3 de TI)
A27: C-19 | B27: Variable | C27: Inductor 47 µH, 3,57 A | D27: Pulse PE-54039 / Renco RL-5472-3 (L39) | E27: Pulse / Renco | F27: 47 µH, 3,57 A, through-hole | G27: 1 | H27: Filtro de salida de la variable | I27: Hoja Convertidores §4 | J27: PCB | K27: https://www.ti.com/lit/ds/symlink/lm2678.pdf | L27: https://www.snapeda.com/search?q=PE-54039 | M27: Verificado en hoja de datos del fabricante (Tabla 7-3 de TI)
A28: C-20 | B28: −12 V | C28: Inductor 33 µH, 4,26 A | D28: Pulse PE-54040 / Renco RL-1283-33-43 (L40) | E28: Pulse / Renco | F28: 33 µH, 4,26 A, through-hole | G28: 1 | H28: Inductor del convertidor inversor | I28: Hoja Convertidores §4: I_pico ≈ 1,9 A | J28: PCB | K28: https://www.ti.com/lit/ds/symlink/lm2678.pdf | L28: https://www.snapeda.com/search?q=PE-54040 | M28: Verificado en hoja de datos del fabricante (Tabla 7-3 de TI)
A29: C-21 | B29: LM2678 (4 salidas) | C29: Diodo Schottky 7,5 A / 45 V | D29: MBR745 | E29: onsemi / Vishay | F29: 7,5 A, 45 V, TO-220 | G29: 4 | H29: Diodo de libre circulación de cada LM2678 | I29: Hoja Convertidores §8 | J29: PCB | K29: https://www.ti.com/lit/ds/symlink/lm2678.pdf | L29: https://www.snapeda.com/search?q=MBR745 | M29: Verificado en hoja de datos del fabricante (Tabla 7-4 de TI)
A30: C-22 | B30: −12 V | C30: Diodo Schottky 3 A / 60 V | D30: SS36 | E30: onsemi / Vishay | F30: 3 A, 60 V, SMA/SMC | G30: 1 | H30: Diodo del convertidor inversor (V_R = Vin + |Vout|) | I30: Hoja Convertidores §8: 60 V ≥ 1,3 · 42,8 V | J30: PCB | K30: https://www.digikey.com/en/products/result?keywords=SS36 | L30: https://www.snapeda.com/search?q=SS36 | M30: Referencia estándar — validar MPN y stock
A31: C-23 | B31: LM2678 (4 salidas) | C31: Capacitor de entrada 1500 µF / 63 V (low-ESR) | D31: Equivalente vigente a Panasonic HFQ C16 | E31: Panasonic / Nichicon / Rubycon | F31: 1500 µF, 63 V, Irms ≥ 2,5 A a 100 kHz | G31: 4 | H31: Capacitor de entrada local de cada LM2678 | I31: Hoja Convertidores §7 | J31: PCB | K31: https://www.digikey.com/en/products/result?keywords=1500uF%2063V%20low%20ESR | L31: Según MPN final | M31: Valor definido — validar referencia vigente
A32: C-24 | B32: +12 V, +5 V, Variable | C32: Capacitor de salida 560 µF / 35 V (low-ESR) | D32: Equivalente vigente a Panasonic HFQ C5 | E32: Panasonic / Nichicon / Rubycon | F32: 560 µF, 35 V, Irms ≥ 1,4 A | G32: 4 | H32: 1 en +12 V, 1 en +5 V y 2 en la variable | I32: Hoja Convertidores §6 | J32: PCB | K32: https://www.digikey.com/en/products/result?keywords=560uF%2035V%20low%20ESR | L32: Según MPN final | M32: Valor definido — validar referencia vigente
... A41: C-33 | B41: LM2678 (4 salidas) | C41: Disipador para TO-220 | D41: Disipador estándar TO-220 | E41: Aavid / Wakefield | F41: Rθsa ≤ 12 °C/W, con tornillo y grasa térmica | G41: 4 | H41: Evacua el calor de cada LM2678 | I41: Hoja Convertidores §9 | J41: PCB | K41: https://www.digikey.com/en/products/result?keywords=heat%20sink%20TO-220%2012%20C/W | L41: No aplica | M41: Valor definido — validar referencia vigente
A42: PROTECCIONES POR SALIDA Y BORNES
A43: C-34 | B43: +12 V y +5 V | C43: PTC reiniciable 7 A (retención) / 14 A (disparo) | D43: Bourns MF-R700 | E43: Bourns | F43: 7 A hold, 14 A trip, 30 V, radial | G43: 2 | H43: Protección de sobrecorriente por salida | I43: Hoja Convertidores §10 | J43: PCB | K43: https://www.bourns.com/docs/product-datasheets/mf-r.pdf | L43: https://www.digikey.com/en/products/result?keywords=MF-R700 | M43: Verificado en hoja de datos del fabricante
A44: C-35 | B44: +3,3 V y Variable | C44: PTC reiniciable 5 A / 10 A | D44: Bourns MF-R500 | E44: Bourns | F44: 5 A hold, 10 A trip, radial | G44: 2 | H44: Protección de sobrecorriente por salida | I44: Hoja Convertidores §10 | J44: PCB | K44: https://www.bourns.com/docs/product-datasheets/mf-r.pdf | L44: https://www.digikey.com/en/products/result?keywords=MF-R500 | M44: Verificado en catálogo (fabricante/distribuidor)
A45: C-36 | B45: −12 V | C45: PTC reiniciable 1,6 A / 3,2 A | D45: Bourns MF-R160 | E45: Bourns | F45: 1,6 A hold, radial | G45: 1 | H45: Protección de sobrecorriente de −12 V | I45: Hoja Convertidores §10 | J45: PCB | K45: https://www.bourns.com/docs/product-datasheets/mf-r.pdf | L45: https://www.digikey.com/en/products/result?keywords=MF-R160 | M45: Verificado en catálogo (fabricante/distribuidor)
A46: C-37 | B46: +12 V | C46: TVS 1500 W | D46: SMCJ13A | E46: Littelfuse | F46: Vwm 13 V, Vc 21,5 V | G46: 1 | H46: Sujeción de sobretensión en +12 V | I46: Hoja Convertidores §10 | J46: PCB | K46: https://www.digikey.com/en/products/result?keywords=SMCJ13A | L46: https://www.snapeda.com/search?q=SMCJ13A | M46: Referencia estándar — validar MPN y stock
A47: C-38 | B47: +5 V | C47: TVS 1500 W | D47: SMCJ6.0A | E47: Littelfuse | F47: Vwm 6 V, Vc 10,3 V | G47: 1 | H47: Sujeción de sobretensión en +5 V | I47: Hoja Convertidores §10 | J47: PCB | K47: https://www.digikey.com/en/products/result?keywords=SMCJ6.0A | L47: https://www.snapeda.com/search?q=SMCJ6.0A | M47: Referencia estándar — validar MPN y stock
A48: C-39 | B48: +3,3 V | C48: Diodo Zener 5 W | D48: 1N5335B | E48: onsemi / Microsemi | F48: 3,9 V, 5 W | G48: 1 | H48: Sujeción de sobretensión en +3,3 V (no existe TVS de 1500 W con Vwm 3,3 V) | I48: Hoja Convertidores §10 | J48: PCB | K48: https://www.digikey.com/en/products/result?keywords=1N5335B | L48: https://www.snapeda.com/search?q=1N5335B | M48: Referencia estándar — validar MPN y stock
...

Sheet Calculos
A1: Cálculos de diseño — Fuente de alimentación multisalida
A2: Todas las cifras se recalculan a partir de las celdas azules (entradas / supuestos). Celdas en negro = fórmulas. Cada fila indica la fórmula usada y su fuente. El detalle por convertidor está en la hoja «Convertidores».
A3: N.º | B3: Parámetro | C3: Valor | D3: Unidad | E3: Fórmula / fundamento | F3: Fuente / nota
A4: 1. SUPUESTOS GENERALES Y DATOS DE LA RED
A5: 1 | B5: Tensión nominal de la red | C5: 120 | D5: V rms | E5: Red monofásica de Colombia (120 V / 60 Hz). | F5: Supuesto — confirmar con el docente
A6: 2 | B6: Frecuencia de la red | C6: 60 | D6: Hz | E6: Red de Colombia. | F6: Supuesto — confirmar con el docente
A7: 3 | B7: Variación admisible de la red | C7: 0.1 | D7: ±% | E7: Se diseña para −10 % / +10 % de la tensión nominal. | F7: Supuesto de diseño
A8: 4 | B8: Tensión de red mínima | C8: =$C$5*(1-$C$7) -> 108 | D8: V rms | E8: V_red·(1 − tol)
A9: 5 | B9: Tensión de red máxima | C9: =$C$5*(1+$C$7) -> 132 | D9: V rms | E9: V_red·(1 + tol)
A10: 6 | B10: Temperatura ambiente interna del gabinete | C10: 40 | D10: °C | E10: Peor caso dentro de la caja cerrada. | F10: Supuesto de diseño
A11: 7 | B11: Temperatura de unión máxima de diseño | C11: 125 | D11: °C | E11: Límite de operación de los convertidores. | F11: Hoja de datos LM2678 (TI, SNVS029L) §5.3
A12: 8 | B12: Tolerancia de regulación de cada salida | C12: 0.03 | D12: ±% | E12: ±2 % a 25 °C y ±3 % en todo el rango de temperatura (LM2678 fijas). | F12: Hoja de datos LM2678 (TI, SNVS029L) §5.5–5.7
A13: 9 | B13: Rizado máximo de salida (pico a pico) | C13: 0.01 | D13: % de Vout | E13: Criterio del fabricante: rizado ≤ 1 % de Vout. | F13: Hoja de datos LM2678 (TI, SNVS029L) §7.1.3
A14: 10 | B14: Rizado máximo de corriente en el inductor | C14: 0.3 | D14: × Iout | E14: El inductor se elige para ΔI_L ≤ 30 % de la corriente máxima. | F14: Hoja de datos LM2678 (TI, SNVS029L) §7.1.2
A15: 11 | B15: Factor de reducción de corriente de retención del PTC | C15: 0.75 | E15: Corriente de retención disminuye con la temperatura (≈50–60 °C dentro del gabinete). | F15: Supuesto — verificar curva de derating Bourns MF-R
A16: 12 | B16: Margen sobre la corriente máxima de salida (PTC) | C16: 1.05 | D16: × | E16: La retención derateada debe superar 1,05 × Imax. | F16: Decisión de diseño
A17: 13 | B17: Factor de uso de fusibles | C17: 0.75 | E17: Un fusible no debe operar de forma continua por encima del 75 % de su corriente nominal. | F17: Práctica de diseño (hojas de datos de fusibles)
A18: 2. POTENCIA TOTAL (resumen; el detalle por salida está en la hoja Convertidores)
A19: 14 | B19: Potencia máxima total de salida (dato del docente) | C19: 151.9 | D19: W | E19: Suma de V·I máximos de las cinco salidas. | F19: Documento del proyecto (PDF) Tabla 3
A20: 15 | B20: Potencia total de salida (recalculada) | C20: =SUM(Convertidores!C10:G10) -> 151.9 | D20: W | E20: Σ |Vout|·Iout | F20: Hoja Convertidores
A21: 16 | B21: Coincidencia con el dato del docente | C21: =IF(ABS($C$20-$C$19)<0.05,"OK","REVISAR") -> OK | E21: Debe ser igual a 151,9 W.
A22: 17 | B22: Potencia de entrada al bus VIN DC (con pérdidas de los convertidores) | C22: =SUM(Convertidores!C12:G12) -> 176.74534 | D22: W | E22: Σ Pout / η de cada convertidor | F22: Hoja Convertidores
A23: 18 | B23: Eficiencia combinada de la etapa DC/DC | C23: =$C$20/$C$22 -> 0.85942861 | E23: P_out_total / P_in_DC
A24: 3. TRANSFORMADOR SELECCIONADO — DATOS DE LA HOJA DE DATOS
A25: 19 | B25: Modelo | C25: Antek AS-4220 (toroidal, con pantalla electrostática) | E25: Selección justificada en las secciones 4 y 5. | F25: Hoja de datos Antek AS-4220
A26: 20 | B26: Potencia nominal | C26: 400 | D26: VA | E26: Dato del fabricante. | F26: Hoja de datos Antek AS-4220
A27: 21 | B27: Tensión nominal de cada secundario | C27: 20 | D27: V rms | E27: Dos secundarios idénticos de 20 V. | F27: Hoja de datos Antek AS-4220
A28: 22 | B28: Corriente nominal de cada secundario | C28: 10 | D28: A rms | E28: Dato del fabricante (2 × 10 A). | F28: Hoja de datos Antek AS-4220
A29: 23 | B29: Número de secundarios conectados en paralelo | C29: 2 | E29: Los dos devanados se conectan en paralelo y en fase para 20 V / 20 A. | F29: Decisión de diseño (verificar fase con multímetro)
A30: 24 | B30: Corriente nominal con secundarios en paralelo | C30: =$C$28*$C$29 -> 20 | D30: A rms | E30: I_cada · N
A31: 25 | B31: Tensión del secundario en vacío (red 120 V, 60 Hz) | C31: 20.7 | D31: V rms | E31: Medida en la prueba de carga del fabricante. | F31: Hoja de datos Antek AS-4220 (tabla de pruebas)
A32: 26 | B32: Tensión del secundario a plena carga (18,6 A) | C32: 19.8 | D32: V rms | E32: Medida en la prueba de carga del fabricante. | F32: Hoja de datos Antek AS-4220 (tabla de pruebas)
A33: 27 | B33: Corriente de la prueba de plena carga | C33: 18.6 | D33: A rms | E33: Corriente a la que se midieron los 19,8 V. | F33: Hoja de datos Antek AS-4220 (tabla de pruebas)
A34: 28 | B34: Regulación del transformador | C34: =($C$31-$C$32)/$C$32 -> 0.045454545 | D34: % | E34: (V_vacío − V_carga) / V_carga
A35: 29 | B35: Eficiencia del transformador | C35: 0.95 | E35: Valor típico de toroidales de 300–500 VA. | F35: Supuesto de diseño
A36: 30 | B36: Aislamiento primario–secundario (prueba dieléctrica) | C36: 3500 | D36: V | E36: Aislamiento galvánico entre red y salidas. | F36: Hoja de datos Antek AS-4220
A37: 4. BUS VIN DC: RECTIFICACIÓN Y FILTRADO
A38: 31 | B38: Caída directa por diodo del puente (con corriente de pico) | C38: 1.1 | D38: V | E38: VF = 1,1 V a 17,5 A. | F38: Hoja de datos GBJ3510 (Diodes Inc.)
A39: 32 | B39: Caída directa por diodo con poca corriente (sin carga) | C39: 0.7 | D39: V | E39: Valor típico a corriente baja. | F39: Supuesto de diseño
A40: 33 | B40: Rizado admisible del bus (pico a pico, peor caso) | C40: 3 | D40: V | E40: Define la capacitancia mínima del filtro. | F40: Decisión de diseño (dato pendiente del PDF)
...

Sheet Convertidores
A1: Diseño de los cinco convertidores DC/DC — cálculos por salida
A2: Metodología del fabricante (hoja de datos LM2678, §7.2: E·T, inductor, capacitores, diodo) y TPS54560B inversor (§8.3). Entradas en azul; todo lo demás son fórmulas.
A4: N.º | B4: Concepto | C4: +12 V / 5 A | D4: +5 V / 5 A | E4: +3,3 V / 3 A | F4: −12 V / 1 A | G4: Variable 1,25–15 V / 3 A | H4: Unidad | I4: Fundamento / fuente
A5: 1. DATOS DE LA SALIDA
A6: 1 | B6: Circuito integrado | C6: LM2678T-12 | D6: LM2678T-5.0 | E6: LM2678T-3.3 | F6: TPS54560B | G6: LM2678T-ADJ | I6: Candidatos del PDF validados contra su hoja de datos.
A7: 2 | B7: Topología | C7: Reductor (buck) | D7: Reductor (buck) | E7: Reductor (buck) | F7: Buck-boost inversor | G7: Reductor (buck) ajustable | I7: −12 V: TPS54560B en configuración inversora (hoja de datos §8.3 y nota SLVA317).
A8: 3 | B8: Tensión de salida (máxima para la variable) | C8: 12 | D8: 5 | E8: 3.3 | F8: -12 | G8: 15 | H8: V | I8: Tabla 1 del PDF.
A9: 4 | B9: Corriente máxima de salida | C9: 5 | D9: 5 | E9: 3 | F9: 1 | G9: 3 | H9: A | I9: Tabla 1 del PDF.
A10: 5 | B10: Potencia máxima de salida | C10: =ABS(C8)*C9 -> 60 | D10: =ABS(D8)*D9 -> 25 | E10: =ABS(E8)*E9 -> 9.9 | F10: =ABS(F8)*F9 -> 12 | G10: =ABS(G8)*G9 -> 45 | H10: W | I10: P = |V|·I
A11: 6 | B11: Eficiencia de diseño (conservadora) | C11: 0.9 | D11: 0.8 | E11: 0.78 | F11: 0.8 | G11: 0.88 | I11: LM2678 datasheet: 92 % (12 V, Vin 24 V), 84 % (5 V), 82 % (3,3 V) a Vin 12 V; se reduce porque aquí Vin ≈ 21–31 V. −12 V: supuesto.
A12: 7 | B12: Potencia tomada del bus VIN DC | C12: =C10/C11 -> 66.666667 | D12: =D10/D11 -> 31.25 | E12: =E10/E11 -> 12.692308 | F12: =F10/F11 -> 15 | G12: =G10/G11 -> 51.136364 | H12: W | I12: P_in = P_out / η
A13: 8 | B13: Pérdidas del convertidor | C13: =C12-C10 -> 6.6666667 | D13: =D12-D10 -> 6.25 | E13: =E12-E10 -> 2.7923077 | F13: =F12-F10 -> 3 | G13: =G12-G10 -> 6.1363636 | H13: W | I13: P_in − P_out
A14: 2. ENTRADA DESDE EL BUS VIN DC
A15: 9 | B15: Tensión mínima del bus | C15: =Calculos!$C$52 -> 20.717891 | D15: =Calculos!$C$52 -> 20.717891 | E15: =Calculos!$C$52 -> 20.717891 | F15: =Calculos!$C$52 -> 20.717891 | G15: =Calculos!$C$52 -> 20.717891 | H15: V | I15: Hoja Calculos §4
A16: 10 | B16: Tensión máxima del bus | C16: =Calculos!$C$63 -> 30.801643 | D16: =Calculos!$C$63 -> 30.801643 | E16: =Calculos!$C$63 -> 30.801643 | F16: =Calculos!$C$63 -> 30.801643 | G16: =Calculos!$C$63 -> 30.801643 | H16: V | I16: Hoja Calculos §4
A17: 11 | B17: Entrada mínima del IC | C17: 15 | D17: 8 | E17: 8 | F17: 4.5 | G17: 8 | H17: V | I17: LM2678-12: 15 V; resto de LM2678: 8 V; TPS54560B: 4,5 V.
A18: 12 | B18: Verificación entrada mínima | C18: =IF(C15>=C17,"OK","REVISAR") -> OK | D18: =IF(D15>=D17,"OK","REVISAR") -> OK | E18: =IF(E15>=E17,"OK","REVISAR") -> OK | F18: =IF(F15>=F17,"OK","REVISAR") -> OK | G18: =IF(G15>=G17,"OK","REVISAR") -> OK | I18: Vin_min ≥ Vin_min_IC
A19: 13 | B19: Tensión máxima vista por el IC | C19: =C16 -> 30.801643 | D19: =D16 -> 30.801643 | E19: =E16 -> 30.801643 | F19: =F16+ABS(F8) -> 42.801643 | G19: =G16 -> 30.801643 | H19: V | I19: Inversor: el IC ve Vin + |Vout|.
A20: 14 | B20: Entrada máxima del IC | C20: 40 | D20: 40 | E20: 40 | F20: 60 | G20: 40 | H20: V | I20: LM2678: 40 V de operación (45 V absolutos); TPS54560B: 60 V.
A21: 15 | B21: Verificación entrada máxima | C21: =IF(C19<=C20,"OK","REVISAR") -> OK | D21: =IF(D19<=D20,"OK","REVISAR") -> OK | E21: =IF(E19<=E20,"OK","REVISAR") -> OK | F21: =IF(F19<=F20,"OK","REVISAR") -> OK | G21: =IF(G19<=G20,"OK","REVISAR") -> OK | I21: Vin_max ≤ límite del IC
A22: 16 | B22: Margen de tensión | C22: =1-C19/C20 -> 0.22995893 | D22: =1-D19/D20 -> 0.22995893 | E22: =1-E19/E20 -> 0.22995893 | F22: =1-F19/F20 -> 0.28663929 | G22: =1-G19/G20 -> 0.22995893 | H22: % | I22: 1 − Vin_max / límite
A23: 3. CICLO DE TRABAJO
A24: 17 | B24: Caída del diodo Schottky | C24: 0.5 | D24: 0.5 | E24: 0.5 | F24: 0.5 | G24: 0.5 | H24: V | I24: Valor típico del fabricante.
A25: 18 | B25: Resistencia del interruptor interno | C25: 0.12 | D25: 0.12 | E25: 0.12 | F25: 0.092 | G25: 0.12 | H25: Ω | I25: LM2678: 0,12 Ω típ.; TPS54560B: 92 mΩ.
A26: 19 | B26: Caída en el interruptor a Imax | C26: =C25*C9 -> 0.6 | D26: =D25*D9 -> 0.6 | E26: =E25*E9 -> 0.36 | F26: =F25*F9 -> 0.092 | G26: =G25*G9 -> 0.36 | H26: V | I26: Vsat = Rds·Iout
A27: 20 | B27: Ciclo de trabajo máximo (Vin mínimo) | C27: =(ABS(C8)+C24)/(C15-C26+C24) -> 0.60626958 | D27: =(ABS(D8)+D24)/(D15-D26+D24) -> 0.26675862 | E27: =(ABS(E8)+E24)/(E15-E26+E24) -> 0.18218525 | F27: =ABS(F8)/(F15+ABS(F8)) -> 0.36677181 | G27: =(ABS(G8)+G24)/(G15-G26+G24) -> 0.74312404 | I27: Buck: D = (Vout+Vd)/(Vin−Vsat+Vd). Inversor: D = |Vo|/(Vin+|Vo|).
A28: 21 | B28: Ciclo de trabajo mínimo (Vin máximo) | C28: =(ABS(C8)+C24)/(C16-C26+C24) -> 0.40714434 | D28: =(ABS(D8)+D24)/(D16-D26+D24) -> 0.17914351 | E28: =(ABS(E8)+E24)/(E16-E26+E24) -> 0.12281184 | F28: =ABS(F8)/(F16+ABS(F8)) -> 0.28036307 | G28: =(ABS(G8)+G24)/(G16-G26+G24) -> 0.50094302 | I28: Misma fórmula con Vin máximo.
A29: 22 | B29: Ciclo de trabajo máximo del IC | C29: 0.91 | D29: 0.91 | E29: 0.91 | F29: — | G29: 0.91 | I29: LM2678: 91 %.
A30: 23 | B30: Verificación del ciclo | C30: =IF(C27<=C29,"OK","REVISAR") -> OK | D30: =IF(D27<=D29,"OK","REVISAR") -> OK | E30: =IF(E27<=E29,"OK","REVISAR") -> OK | F30: — | G30: =IF(G27<=G29,"OK","REVISAR") -> OK | I30: D_max ≤ D_límite
A31: 4. INDUCTOR
A32: 24 | B32: Frecuencia de conmutación | C32: 260 | D32: 260 | E32: 260 | F32: 400 | G32: 260 | H32: kHz | I32: LM2678: 260 kHz fijos. TPS54560B: 400 kHz (valor de diseño; RT se fija con la ecuación del datasheet en el esquemático).
A33: 25 | B33: Constante E·T (voltios-microsegundo) | C33: =(C16-C26-ABS(C8))*(ABS(C8)+C24)/(C16-C26+C24)*1000/C32 -> 28.502676 | D33: =(D16-D26-ABS(D8))*(ABS(D8)+D24)/(D16-D26+D24)*1000/D32 -> 17.364272 | E33: =(E16-E26-ABS(E8))*(ABS(E8)+E24)/(E16-E26+E24)*1000/E32 -> 12.820442 | F33: — | G33: =(G16-G26-ABS(G8))*(ABS(G8)+G24)/(G16-G26+G24)*1000/G32 -> 29.751474 | H33: V·µs | I33: Ecuación (3) del datasheet LM2678.
A34: 26 | B34: Inductancia mínima (rizado ≤ 30 %) | C34: =C33/(Calculos!$C$14*C9) -> 19.001784 | D34: =D33/(Calculos!$C$14*D9) -> 11.576181 | E34: =E33/(Calculos!$C$14*E9) -> 14.244936 | F34: — | G34: =G33/(Calculos!$C$14*G9) -> 33.057193 | H34: µH | I34: L ≥ E·T / (0,3·Iout)
A35: 27 | B35: Inductancia seleccionada | C35: 22 | D35: 22 | E35: 22 | F35: 33 | G35: 47 | H35: µH | I35: Valores de la Tabla 7-3 del LM2678. ADJ: 33–47 µH recomendados para tensiones bajas.
A36: 28 | B36: Rizado de corriente del inductor (pico a pico) | C36: =C33/C35 -> 1.2955762 | D36: =D33/D35 -> 0.78928509 | E36: =E33/E35 -> 0.58274738 | F36: =F15*F27/(F32*1000*F35*0.000001) -> 0.57566199 | G36: =G33/G35 -> 0.63301008 | H36: A | I36: Buck: E·T/L (Vin máx). Inversor: Vin·D/(f·L) (Vin mín).
A37: 29 | B37: Corriente media del inductor | C37: =C9 -> 5 | D37: =D9 -> 5 | E37: =E9 -> 3 | F37: =F9/(1-F27) -> 1.5792095 | G37: =G9 -> 3 | H37: A | I37: Inversor: Iout/(1−D).
A38: 30 | B38: Corriente pico del inductor | C38: =C37+C36/2 -> 5.6477881 | D38: =D37+D36/2 -> 5.3946425 | E38: =E37+E36/2 -> 3.2913737 | F38: =F37+F36/2 -> 1.8670405 | G38: =G37+G36/2 -> 3.316505 | H38: A | I38: I_prom + ΔI/2
A39: 31 | B39: Corriente nominal del inductor elegido | C39: 5.22 | D39: 5.22 | E39: 5.22 | F39: 4.26 | G39: 3.57 | H39: A | I39: Tabla 7-3 LM2678 (L41, L40, L39).
A40: 32 | B40: Verificación del inductor | C40: =IF(AND(C35>=C34,C38<=C39),"OK","REVISAR") -> REVISAR | D40: =IF(AND(D35>=D34,D38<=D39),"OK","REVISAR") -> REVISAR | E40: =IF(AND(E35>=E34,E38<=E39),"OK","REVISAR") -> OK | F40: =IF(F38<=F39,"OK","REVISAR") -> OK | G40: =IF(AND(G35>=G34,G38<=G39),"OK","REVISAR") -> OK | I40: L ≥ L_min e I_pico ≤ I_nominal
A41: 33 | B41: Referencia del inductor | C41: Renco RL-1283-22-43 (L41) | D41: Renco RL-1283-22-43 (L41) | E41: Renco RL-1283-22-43 (L41) | F41: Pulse PE-54040 / Renco RL-1283-33-43 (L40) | G41: Pulse PE-54039 / Renco RL-5472-3 (L39) | I41: Referencias de la Tabla 7-3 del datasheet LM2678.
...

Sheet Decisiones
A1: Datos pendientes del PDF (§9) — resueltos
A2: Cada dato que el documento dejaba «por definir» tiene aquí su decisión, su valor y su justificación. La última columna marca lo que conviene validar con el docente.
A3: ID | B3: Dato pendiente (PDF §9) | C3: Decisión | D3: Valor | E3: Unidad | F3: Justificación / cálculo | G3: ¿Confirmar con el docente?
A4: D-01 | B4: Transformador: tensión del secundario | C4: Antek AS-4220, secundarios en paralelo | D4: =Calculos!$C$27 -> 20 | E4: V rms | F4: Con 20 V el bus nunca baja de la tensión requerida (Calculos §4) y nunca supera los 40 V de los LM2678. | G4: No
A5: D-02 | B5: Transformador: corriente nominal | C5: Secundarios 2 × 10 A en paralelo | D5: =Calculos!$C$30 -> 20 | E5: A rms | F5: La corriente RMS requerida es menor (Calculos §5). | G5: No
A6: D-03 | B6: Transformador: potencia | C6: Transformador de 400 VA | D6: =Calculos!$C$26 -> 400 | E6: VA | F6: Potencia mínima con margen del 20 %: ver Calculos §5. El AS-3220 (300 VA) queda al límite; el AN-5220 (500 VA) es innecesario. | G6: No
A7: D-04 | B7: Tensión mínima del bus VIN DC | C7: Mínimo requerido y mínimo obtenido | D7: =Calculos!$C$59 -> 17.892967 | E7: V | F7: Requerido (LM2678-12 y salida variable a 15 V + margen). El valor obtenido en el peor caso está en Calculos §4. | G7: No
A8: D-05 | B8: Rizado admisible del bus | C8: Rizado pico a pico máximo | D8: =Calculos!$C$40 -> 3 | E8: V | F8: Define C ≥ I/(2·f·ΔV). Con 30 000 µF el rizado real es menor (Calculos §4). | G8: No
A9: D-06 | B9: ¿Todas las salidas a corriente máxima a la vez? | C9: SÍ — se diseña para el peor caso | D9: =Calculos!$C$22 -> 176.74534 | E9: W | F9: Potencia al bus con las cinco salidas a plena carga, incluyendo pérdidas. | G9: Sí
A10: D-07 | B10: Tolerancia de regulación de cada salida | C10: ±3 % (carga y temperatura) | D10: =Calculos!$C$12 -> 0.03 | E10: ±% | F10: Especificación del LM2678 (±2 % a 25 °C). | G10: No
A11: D-08 | B11: Rizado de cada salida | C11: ≤ 1 % de Vout (pico a pico) | D11: =Calculos!$C$13 -> 0.01 | E11: % de Vout | F11: Criterio del fabricante; verificado en Convertidores §6. | G11: No
A12: D-09 | B12: Topología del convertidor de −12 V | C12: Buck-boost inversor con TPS54560B | D12: Inversor | F12: La hoja de datos del TPS54560B incluye la sección «Inverting Power» (§8.3) y la nota SLVA317. Vin del IC = Vbus + 12 V < 60 V. | G12: No
A13: D-10 | B13: Protección de entrada: tipo y umbrales | C13: Fusible T4A + varistor 150 Vac + NTC 10 Ω | D13: =Calculos!$C$93 -> 4 | E13: A | F13: Fusible ≥ I_primario/0,75; NTC limita el arranque (Calculos §6). | G13: No
A14: D-11 | B14: Protección del bus DC: tipo y umbrales | C14: Fusible ATO 15 A + TVS SMCJ30A + sangrado | D14: =Calculos!$C$118 -> 15 | E14: A | F14: Fusible ≥ I_DC/0,75; el TVS no conduce con el bus máximo (Calculos §8). | G14: No
A15: D-12 | B15: Protección de salidas: tipo y umbrales | C15: PTC Bourns MF-R + diodo de sujeción por salida | D15: Ver hoja | F15: Retención derateada ≥ 1,05·Imax; Vwm del TVS ≥ Vout·1,03 (Convertidores §10). | G15: No
A16: D-13 | B16: Eficiencia objetivo | C16: Total ≥ 70 %; DC/DC ≥ 80 % | D16: =Calculos!$C$140 -> 0.7 | F16: Eficiencia total calculada en Calculos §10. | G16: No
A17: D-14 | B17: Referencia común (tierra) | C17: GND común a las cinco salidas; flotante respecto a PE | D17: GND común | F17: El transformador aísla la red; el chasis va a PE; puente opcional GND–chasis. | G17: Sí
A18: D-15 | B18: Ubicación de la etapa de red | C18: Módulo IEC, fusible, interruptor, NTC y varistor cableados en el chasis | D18: Fuera de PCB | F18: La PCB trabaja solo con baja tensión (secundario). | G18: Sí
A19: D-16 | B19: Tensión y frecuencia de red | C19: 120 V / 60 Hz (Colombia) | D19: =Calculos!$C$5 -> 120 | E19: V rms | F19: Base de todos los cálculos del bus. | G19: Sí
